Workbook

Sheet 1-Carga de datos

Sheet 2-Resumen
B1: Salario | C1: Edad
A2: Promedio | B2: =AVERAGE(moras[SALARIO]) -> 22574401 | C2: =AVERAGE(moras[EDAD]) -> 41.906344
A3: Desviación estándar | B3: =STDEV(moras[SALARIO]) -> 60099618 | C3: =STDEV(moras[EDAD]) -> 14.169257 | F3: Tipo de aseguramiento
A4: Moda | B4: =MODE(moras[SALARIO]) -> 297046 | C4: =MODE(moras[EDAD]) -> 36 | E4: Moda | F4: {=_xlfn.LET(_xlpm.col, moras[TIPO_ASEGURAMIENTO], _xlpm.unicos, _xlfn.UNIQUE(_xlpm.col), _xlpm.conteos, COUNTIF(_xlpm.col, _xlpm.unicos), INDEX(_xlpm.unicos, _xlfn.XMATCH(MAX(_xlpm.conteos), _xlpm.conteos)))} -> ASALARIADO
A5: Máximo | B5: =MAX(moras[SALARIO]) -> 1158018598 | C5: =MAX(moras[EDAD]) -> 99
A6: Mínimo | B6: =MIN(moras[SALARIO]) -> 10 | C6: =MIN(moras[EDAD]) -> 14
A7: Mediana | B7: =MEDIAN(moras[SALARIO]) -> 639148 | C7: =MEDIAN(moras[EDAD]) -> 40

Sheet moras
A1: IDENTIFICACION | B1: SEXO | C1: SALARIO | D1: SALARIO_GRUPO | E1: SALARIO SIN NA´S | F1: Z-CORE | G1: INDICADOR_VALOR_ATÍPICO_SALARIO | H1: TIPO_ASEGURAMIENTO | I1: TIPO_ASEGURAMIENTO_SIN_NA´S | J1: SECTOR | K1: INDICADOR_ACTIVO | L1: INDICADOR.EXTRANJERO | M1: INDICADOR_MOROSO | N1: EDAD | O1: EDAD_SIN_NA´S | P1: EDAD_GRUPO | Q1: Z-CORE E | R1: INDICADOR_VALOR_ATÍPICO_EDAD
A2: 151 | B2: MUJER | C2: 299647 | D2: =IF(moras[[#This Row],[SALARIO]] <= '8-Morosidad en númericas'!$C$3, "BAJO", IF(moras[[#This Row],[SALARIO]] <= '8-Morosidad en númericas'!$C$4, "MEDIO-BAJO", IF(moras[[#This Row],[SALARIO]] <='8-Morosidad en númericas'!$C$5, "MEDIO-ALTO", "ALTO"))) -> BAJO | E2: =IF(moras[[#This Row],[SALARIO]]="",'2-Resumen'!$B$7, moras[[#This Row],[SALARIO]]) -> 299647 | F2: =STANDARDIZE(moras[[#This Row],[SALARIO]],'2-Resumen'!$B$2,'2-Resumen'!$B$3) -> -0.37063054 | G2: =IF(ABS(moras[[#This Row],[Z-CORE]])> 1.96,"Sí", "No") -> No | I2: =IF(moras[[#This Row],[TIPO_ASEGURAMIENTO]] = "", '2-Resumen'!$F$4, moras[[#This Row],[TIPO_ASEGURAMIENTO]]) -> ASALARIADO | J2: SECTOR PRIVADO | K2: SI | L2: NO | M2: NO | N2: 40 | O2: =IF(moras[[#This Row],[EDAD]]="", '2-Resumen'!$C$7, moras[[#This Row],[EDAD]]) -> 40 | P2: =FLOOR(moras[[#This Row],[EDAD_SIN_NA´S]],10) -> 40 | Q2: =STANDARDIZE(moras[[#This Row],[EDAD]],'2-Resumen'!$C$2, '2-Resumen'!$C$3) -> -0.13454084 | R2: =IF(ABS(moras[[#This Row],[Z-CORE E]]) > 1.96, "Sí", "No") -> No
A3: 1 | B3: HOMBRE | D3: =IF(moras[[#This Row],[SALARIO]] <= '8-Morosidad en númericas'!$C$3, "BAJO", IF(moras[[#This Row],[SALARIO]] <= '8-Morosidad en númericas'!$C$4, "MEDIO-BAJO", IF(moras[[#This Row],[SALARIO]] <='8-Morosidad en númericas'!$C$5, "MEDIO-ALTO", "ALTO"))) -> BAJO | E3: =IF(moras[[#This Row],[SALARIO]]="",'2-Resumen'!$B$7, moras[[#This Row],[SALARIO]]) -> 639148 | F3: =STANDARDIZE(moras[[#This Row],[SALARIO]],'2-Resumen'!$B$2,'2-Resumen'!$B$3) -> -0.37561638 | G3: =IF(ABS(moras[[#This Row],[Z-CORE]])> 1.96,"Sí", "No") -> No | H3: ASALARIADO | I3: =IF(moras[[#This Row],[TIPO_ASEGURAMIENTO]] = "", '2-Resumen'!$F$4, moras[[#This Row],[TIPO_ASEGURAMIENTO]]) -> ASALARIADO | J3: SECTOR PUBLICO | K3: SI | L3: NO | M3: NO | N3: 42 | O3: =IF(moras[[#This Row],[EDAD]]="", '2-Resumen'!$C$7, moras[[#This Row],[EDAD]]) -> 42 | P3: =FLOOR(moras[[#This Row],[EDAD_SIN_NA´S]],10) -> 40 | Q3: =STANDARDIZE(moras[[#This Row],[EDAD]],'2-Resumen'!$C$2, '2-Resumen'!$C$3) -> 0.0066098168 | R3: =IF(ABS(moras[[#This Row],[Z-CORE E]]) > 1.96, "Sí", "No") -> No
A4: 3 | B4: MUJER | C4: 27048601 | D4: =IF(moras[[#This Row],[SALARIO]] <= '8-Morosidad en númericas'!$C$3, "BAJO", IF(moras[[#This Row],[SALARIO]] <= '8-Morosidad en númericas'!$C$4, "MEDIO-BAJO", IF(moras[[#This Row],[SALARIO]] <='8-Morosidad en númericas'!$C$5, "MEDIO-ALTO", "ALTO"))) -> ALTO | E4: =IF(moras[[#This Row],[SALARIO]]="",'2-Resumen'!$B$7, moras[[#This Row],[SALARIO]]) -> 27048601 | F4: =STANDARDIZE(moras[[#This Row],[SALARIO]],'2-Resumen'!$B$2,'2-Resumen'!$B$3) -> 0.074446392 | G4: =IF(ABS(moras[[#This Row],[Z-CORE]])> 1.96,"Sí", "No") -> No | H4: ASALARIADO | I4: =IF(moras[[#This Row],[TIPO_ASEGURAMIENTO]] = "", '2-Resumen'!$F$4, moras[[#This Row],[TIPO_ASEGURAMIENTO]]) -> ASALARIADO | J4: SECTOR PRIVADO | K4: SI | L4: NO | M4: NO | N4: 45 | O4: =IF(moras[[#This Row],[EDAD]]="", '2-Resumen'!$C$7, moras[[#This Row],[EDAD]]) -> 45 | P4: =FLOOR(moras[[#This Row],[EDAD_SIN_NA´S]],10) -> 40 | Q4: =STANDARDIZE(moras[[#This Row],[EDAD]],'2-Resumen'!$C$2, '2-Resumen'!$C$3) -> 0.21833581 | R4: =IF(ABS(moras[[#This Row],[Z-CORE E]]) > 1.96, "Sí", "No") -> No
A5: 4 | B5: MUJER | C5: 54494983 | D5: =IF(moras[[#This Row],[SALARIO]] <= '8-Morosidad en númericas'!$C$3, "BAJO", IF(moras[[#This Row],[SALARIO]] <= '8-Morosidad en númericas'!$C$4, "MEDIO-BAJO", IF(moras[[#This Row],[SALARIO]] <='8-Morosidad en númericas'!$C$5, "MEDIO-ALTO", "ALTO"))) -> ALTO | E5: =IF(moras[[#This Row],[SALARIO]]="",'2-Resumen'!$B$7, moras[[#This Row],[SALARIO]]) -> 54494983 | F5: =STANDARDIZE(moras[[#This Row],[SALARIO]],'2-Resumen'!$B$2,'2-Resumen'!$B$3) -> 0.53112786 | G5: =IF(ABS(moras[[#This Row],[Z-CORE]])> 1.96,"Sí", "No") -> No | H5: ASALARIADO | I5: =IF(moras[[#This Row],[TIPO_ASEGURAMIENTO]] = "", '2-Resumen'!$F$4, moras[[#This Row],[TIPO_ASEGURAMIENTO]]) -> ASALARIADO | J5: SECTOR PRIVADO | K5: SI | L5: NO | M5: NO | N5: 49 | O5: =IF(moras[[#This Row],[EDAD]]="", '2-Resumen'!$C$7, moras[[#This Row],[EDAD]]) -> 49 | P5: =FLOOR(moras[[#This Row],[EDAD_SIN_NA´S]],10) -> 40 | Q5: =STANDARDIZE(moras[[#This Row],[EDAD]],'2-Resumen'!$C$2, '2-Resumen'!$C$3) -> 0.50063713 | R5: =IF(ABS(moras[[#This Row],[Z-CORE E]]) > 1.96, "Sí", "No") -> No
A6: 5 | B6: MUJER | C6: 210000 | D6: =IF(moras[[#This Row],[SALARIO]] <= '8-Morosidad en númericas'!$C$3, "BAJO", IF(moras[[#This Row],[SALARIO]] <= '8-Morosidad en númericas'!$C$4, "MEDIO-BAJO", IF(moras[[#This Row],[SALARIO]] <='8-Morosidad en númericas'!$C$5, "MEDIO-ALTO", "ALTO"))) -> BAJO | E6: =IF(moras[[#This Row],[SALARIO]]="",'2-Resumen'!$B$7, moras[[#This Row],[SALARIO]]) -> 210000 | F6: =STANDARDIZE(moras[[#This Row],[SALARIO]],'2-Resumen'!$B$2,'2-Resumen'!$B$3) -> -0.37212218 | G6: =IF(ABS(moras[[#This Row],[Z-CORE]])> 1.96,"Sí", "No") -> No | H6: ASALARIADO | I6: =IF(moras[[#This Row],[TIPO_ASEGURAMIENTO]] = "", '2-Resumen'!$F$4, moras[[#This Row],[TIPO_ASEGURAMIENTO]]) -> ASALARIADO | J6: SECTOR PRIVADO | K6: SI | L6: NO | M6: NO | N6: 42 | O6: =IF(moras[[#This Row],[EDAD]]="", '2-Resumen'!$C$7, moras[[#This Row],[EDAD]]) -> 42 | P6: =FLOOR(moras[[#This Row],[EDAD_SIN_NA´S]],10) -> 40 | Q6: =STANDARDIZE(moras[[#This Row],[EDAD]],'2-Resumen'!$C$2, '2-Resumen'!$C$3) -> 0.0066098168 | R6: =IF(ABS(moras[[#This Row],[Z-CORE E]]) > 1.96, "Sí", "No") -> No
A7: 6 | B7: HOMBRE | C7: 397150 | D7: =IF(moras[[#This Row],[SALARIO]] <= '8-Morosidad en númericas'!$C$3, "BAJO", IF(moras[[#This Row],[SALARIO]] <= '8-Morosidad en númericas'!$C$4, "MEDIO-BAJO", IF(moras[[#This Row],[SALARIO]] <='8-Morosidad en númericas'!$C$5, "MEDIO-ALTO", "ALTO"))) -> MEDIO-BAJO | E7: =IF(moras[[#This Row],[SALARIO]]="",'2-Resumen'!$B$7, moras[[#This Row],[SALARIO]]) -> 397150 | F7: =STANDARDIZE(moras[[#This Row],[SALARIO]],'2-Resumen'!$B$2,'2-Resumen'!$B$3) -> -0.36900819 | G7: =IF(ABS(moras[[#This Row],[Z-CORE]])> 1.96,"Sí", "No") -> No | H7: ASALARIADO | I7: =IF(moras[[#This Row],[TIPO_ASEGURAMIENTO]] = "", '2-Resumen'!$F$4, moras[[#This Row],[TIPO_ASEGURAMIENTO]]) -> ASALARIADO | J7: SECTOR PRIVADO | K7: SI | L7: NO | M7: NO | N7: 44 | O7: =IF(moras[[#This Row],[EDAD]]="", '2-Resumen'!$C$7, moras[[#This Row],[EDAD]]) -> 44 | P7: =FLOOR(moras[[#This Row],[EDAD_SIN_NA´S]],10) -> 40 | Q7: =STANDARDIZE(moras[[#This Row],[EDAD]],'2-Resumen'!$C$2, '2-Resumen'!$C$3) -> 0.14776048 | R7: =IF(ABS(moras[[#This Row],[Z-CORE E]]) > 1.96, "Sí", "No") -> No
A8: 7 | B8: HOMBRE | C8: 854712 | D8: =IF(moras[[#This Row],[SALARIO]] <= '8-Morosidad en númericas'!$C$3, "BAJO", IF(moras[[#This Row],[SALARIO]] <= '8-Morosidad en númericas'!$C$4, "MEDIO-BAJO", IF(moras[[#This Row],[SALARIO]] <='8-Morosidad en númericas'!$C$5, "MEDIO-ALTO", "ALTO"))) -> MEDIO-ALTO | E8: =IF(moras[[#This Row],[SALARIO]]="",'2-Resumen'!$B$7, moras[[#This Row],[SALARIO]]) -> 854712 | F8: =STANDARDIZE(moras[[#This Row],[SALARIO]],'2-Resumen'!$B$2,'2-Resumen'!$B$3) -> -0.36139479 | G8: =IF(ABS(moras[[#This Row],[Z-CORE]])> 1.96,"Sí", "No") -> No | H8: ASALARIADO | I8: =IF(moras[[#This Row],[TIPO_ASEGURAMIENTO]] = "", '2-Resumen'!$F$4, moras[[#This Row],[TIPO_ASEGURAMIENTO]]) -> ASALARIADO | J8: SECTOR PRIVADO | K8: SI | L8: NO | M8: NO | N8: 38 | O8: =IF(moras[[#This Row],[EDAD]]="", '2-Resumen'!$C$7, moras[[#This Row],[EDAD]]) -> 38 | P8: =FLOOR(moras[[#This Row],[EDAD_SIN_NA´S]],10) -> 30 | Q8: =STANDARDIZE(moras[[#This Row],[EDAD]],'2-Resumen'!$C$2, '2-Resumen'!$C$3) -> -0.2756915 | R8: =IF(ABS(moras[[#This Row],[Z-CORE E]]) > 1.96, "Sí", "No") -> No
A9: 8 | B9: HOMBRE | C9: 401000 | D9: =IF(moras[[#This Row],[SALARIO]] <= '8-Morosidad en númericas'!$C$3, "BAJO", IF(moras[[#This Row],[SALARIO]] <= '8-Morosidad en númericas'!$C$4, "MEDIO-BAJO", IF(moras[[#This Row],[SALARIO]] <='8-Morosidad en númericas'!$C$5, "MEDIO-ALTO", "ALTO"))) -> MEDIO-BAJO | E9: =IF(moras[[#This Row],[SALARIO]]="",'2-Resumen'!$B$7, moras[[#This Row],[SALARIO]]) -> 401000 | F9: =STANDARDIZE(moras[[#This Row],[SALARIO]],'2-Resumen'!$B$2,'2-Resumen'!$B$3) -> -0.36894413 | G9: =IF(ABS(moras[[#This Row],[Z-CORE]])> 1.96,"Sí", "No") -> No | H9: ASALARIADO | I9: =IF(moras[[#This Row],[TIPO_ASEGURAMIENTO]] = "", '2-Resumen'!$F$4, moras[[#This Row],[TIPO_ASEGURAMIENTO]]) -> ASALARIADO | J9: SECTOR PRIVADO | K9: SI | L9: SI | M9: SI | N9: 36 | O9: =IF(moras[[#This Row],[EDAD]]="", '2-Resumen'!$C$7, moras[[#This Row],[EDAD]]) -> 36 | P9: =FLOOR(moras[[#This Row],[EDAD_SIN_NA´S]],10) -> 30 | Q9: =STANDARDIZE(moras[[#This Row],[EDAD]],'2-Resumen'!$C$2, '2-Resumen'!$C$3) -> -0.41684216 | R9: =IF(ABS(moras[[#This Row],[Z-CORE E]]) > 1.96, "Sí", "No") -> No
A10: 9 | B10: MUJER | C10: 26470396 | D10: =IF(moras[[#This Row],[SALARIO]] <= '8-Morosidad en númericas'!$C$3, "BAJO", IF(moras[[#This Row],[SALARIO]] <= '8-Morosidad en númericas'!$C$4, "MEDIO-BAJO", IF(moras[[#This Row],[SALARIO]] <='8-Morosidad en númericas'!$C$5, "MEDIO-ALTO", "ALTO"))) -> ALTO | E10: =IF(moras[[#This Row],[SALARIO]]="",'2-Resumen'!$B$7, moras[[#This Row],[SALARIO]]) -> 26470396 | F10: =STANDARDIZE(moras[[#This Row],[SALARIO]],'2-Resumen'!$B$2,'2-Resumen'!$B$3) -> 0.064825616 | G10: =IF(ABS(moras[[#This Row],[Z-CORE]])> 1.96,"Sí", "No") -> No | H10: ASALARIADO | I10: =IF(moras[[#This Row],[TIPO_ASEGURAMIENTO]] = "", '2-Resumen'!$F$4, moras[[#This Row],[TIPO_ASEGURAMIENTO]]) -> ASALARIADO | J10: SECTOR PRIVADO | K10: SI | L10: NO | M10: NO | N10: 21 | O10: =IF(moras[[#This Row],[EDAD]]="", '2-Resumen'!$C$7, moras[[#This Row],[EDAD]]) -> 21 | P10: =FLOOR(moras[[#This Row],[EDAD_SIN_NA´S]],10) -> 20 | Q10: =STANDARDIZE(moras[[#This Row],[EDAD]],'2-Resumen'!$C$2, '2-Resumen'!$C$3) -> -1.4754721 | R10: =IF(ABS(moras[[#This Row],[Z-CORE E]]) > 1.96, "Sí", "No") -> No
A11: 10 | B11: HOMBRE | C11: 467712685 | D11: =IF(moras[[#This Row],[SALARIO]] <= '8-Morosidad en númericas'!$C$3, "BAJO", IF(moras[[#This Row],[SALARIO]] <= '8-Morosidad en númericas'!$C$4, "MEDIO-BAJO", IF(moras[[#This Row],[SALARIO]] <='8-Morosidad en númericas'!$C$5, "MEDIO-ALTO", "ALTO"))) -> ALTO | E11: =IF(moras[[#This Row],[SALARIO]]="",'2-Resumen'!$B$7, moras[[#This Row],[SALARIO]]) -> 467712685 | F11: =STANDARDIZE(moras[[#This Row],[SALARIO]],'2-Resumen'!$B$2,'2-Resumen'!$B$3) -> 7.406674 | G11: =IF(ABS(moras[[#This Row],[Z-CORE]])> 1.96,"Sí", "No") -> Sí | H11: ASALARIADO | I11: =IF(moras[[#This Row],[TIPO_ASEGURAMIENTO]] = "", '2-Resumen'!$F$4, moras[[#This Row],[TIPO_ASEGURAMIENTO]]) -> ASALARIADO | J11: SECTOR PRIVADO | K11: SI | L11: NO | M11: NO | N11: 40 | O11: =IF(moras[[#This Row],[EDAD]]="", '2-Resumen'!$C$7, moras[[#This Row],[EDAD]]) -> 40 | P11: =FLOOR(moras[[#This Row],[EDAD_SIN_NA´S]],10) -> 40 | Q11: =STANDARDIZE(moras[[#This Row],[EDAD]],'2-Resumen'!$C$2, '2-Resumen'!$C$3) -> -0.13454084 | R11: =IF(ABS(moras[[#This Row],[Z-CORE E]]) > 1.96, "Sí", "No") -> No
A12: 11 | B12: MUJER | C12: 1200000 | D12: =IF(moras[[#This Row],[SALARIO]] <= '8-Morosidad en númericas'!$C$3, "BAJO", IF(moras[[#This Row],[SALARIO]] <= '8-Morosidad en númericas'!$C$4, "MEDIO-BAJO", IF(moras[[#This Row],[SALARIO]] <='8-Morosidad en númericas'!$C$5, "MEDIO-ALTO", "ALTO"))) -> MEDIO-ALTO | E12: =IF(moras[[#This Row],[SALARIO]]="",'2-Resumen'!$B$7, moras[[#This Row],[SALARIO]]) -> 1200000 | F12: =STANDARDIZE(moras[[#This Row],[SALARIO]],'2-Resumen'!$B$2,'2-Resumen'!$B$3) -> -0.35564953 | G12: =IF(ABS(moras[[#This Row],[Z-CORE]])> 1.96,"Sí", "No") -> No | H12: ASALARIADO | I12: =IF(moras[[#This Row],[TIPO_ASEGURAMIENTO]] = "", '2-Resumen'!$F$4, moras[[#This Row],[TIPO_ASEGURAMIENTO]]) -> ASALARIADO | J12: SECTOR PRIVADO | K12: SI | L12: NO | M12: NO | N12: 30 | O12: =IF(moras[[#This Row],[EDAD]]="", '2-Resumen'!$C$7, moras[[#This Row],[EDAD]]) -> 30 | P12: =FLOOR(moras[[#This Row],[EDAD_SIN_NA´S]],10) -> 30 | Q12: =STANDARDIZE(moras[[#This Row],[EDAD]],'2-Resumen'!$C$2, '2-Resumen'!$C$3) -> -0.84029414 | R12: =IF(ABS(moras[[#This Row],[Z-CORE E]]) > 1.96, "Sí", "No") -> No
A13: 12 | B13: MUJER | C13: 1030132 | D13: =IF(moras[[#This Row],[SALARIO]] <= '8-Morosidad en númericas'!$C$3, "BAJO", IF(moras[[#This Row],[SALARIO]] <= '8-Morosidad en númericas'!$C$4, "MEDIO-BAJO", IF(moras[[#This Row],[SALARIO]] <='8-Morosidad en númericas'!$C$5, "MEDIO-ALTO", "ALTO"))) -> MEDIO-ALTO | E13: =IF(moras[[#This Row],[SALARIO]]="",'2-Resumen'!$B$7, moras[[#This Row],[SALARIO]]) -> 1030132 | F13: =STANDARDIZE(moras[[#This Row],[SALARIO]],'2-Resumen'!$B$2,'2-Resumen'!$B$3) -> -0.35847597 | G13: =IF(ABS(moras[[#This Row],[Z-CORE]])> 1.96,"Sí", "No") -> No | H13: ASALARIADO | I13: =IF(moras[[#This Row],[TIPO_ASEGURAMIENTO]] = "", '2-Resumen'!$F$4, moras[[#This Row],[TIPO_ASEGURAMIENTO]]) -> ASALARIADO | J13: SECTOR PUBLICO | K13: SI | L13: NO | M13: SI | N13: 58 | O13: =IF(moras[[#This Row],[EDAD]]="", '2-Resumen'!$C$7, moras[[#This Row],[EDAD]]) -> 58 | P13: =FLOOR(moras[[#This Row],[EDAD_SIN_NA´S]],10) -> 50 | Q13: =STANDARDIZE(moras[[#This Row],[EDAD]],'2-Resumen'!$C$2, '2-Resumen'!$C$3) -> 1.1358151 | R13: =IF(ABS(moras[[#This Row],[Z-CORE E]]) > 1.96, "Sí", "No") -> No
A14: 13 | B14: HOMBRE | C14: 7312875 | D14: =IF(moras[[#This Row],[SALARIO]] <= '8-Morosidad en númericas'!$C$3, "BAJO", IF(moras[[#This Row],[SALARIO]] <= '8-Morosidad en númericas'!$C$4, "MEDIO-BAJO", IF(moras[[#This Row],[SALARIO]] <='8-Morosidad en númericas'!$C$5, "MEDIO-ALTO", "ALTO"))) -> MEDIO-ALTO | E14: =IF(moras[[#This Row],[SALARIO]]="",'2-Resumen'!$B$7, moras[[#This Row],[SALARIO]]) -> 7312875 | F14: =STANDARDIZE(moras[[#This Row],[SALARIO]],'2-Resumen'!$B$2,'2-Resumen'!$B$3) -> -0.25393716 | G14: =IF(ABS(moras[[#This Row],[Z-CORE]])> 1.96,"Sí", "No") -> No | H14: ASALARIADO | I14: =IF(moras[[#This Row],[TIPO_ASEGURAMIENTO]] = "", '2-Resumen'!$F$4, moras[[#This Row],[TIPO_ASEGURAMIENTO]]) -> ASALARIADO | J14: SECTOR PUBLICO | K14: SI | L14: NO | M14: NO | N14: 40 | O14: =IF(moras[[#This Row],[EDAD]]="", '2-Resumen'!$C$7, moras[[#This Row],[EDAD]]) -> 40 | P14: =FLOOR(moras[[#This Row],[EDAD_SIN_NA´S]],10) -> 40 | Q14: =STANDARDIZE(moras[[#This Row],[EDAD]],'2-Resumen'!$C$2, '2-Resumen'!$C$3) -> -0.13454084 | R14: =IF(ABS(moras[[#This Row],[Z-CORE E]]) > 1.96, "Sí", "No") -> No
A15: 16 | B15: MUJER | C15: 19434895 | D15: =IF(moras[[#This Row],[SALARIO]] <= '8-Morosidad en númericas'!$C$3, "BAJO", IF(moras[[#This Row],[SALARIO]] <= '8-Morosidad en númericas'!$C$4, "MEDIO-BAJO", IF(moras[[#This Row],[SALARIO]] <='8-Morosidad en númericas'!$C$5, "MEDIO-ALTO", "ALTO"))) -> MEDIO-ALTO | E15: =IF(moras[[#This Row],[SALARIO]]="",'2-Resumen'!$B$7, moras[[#This Row],[SALARIO]]) -> 19434895 | F15: =STANDARDIZE(moras[[#This Row],[SALARIO]],'2-Resumen'!$B$2,'2-Resumen'!$B$3) -> -0.052238372 | G15: =IF(ABS(moras[[#This Row],[Z-CORE]])> 1.96,"Sí", "No") -> No | H15: ASALARIADO | I15: =IF(moras[[#This Row],[TIPO_ASEGURAMIENTO]] = "", '2-Resumen'!$F$4, moras[[#This Row],[TIPO_ASEGURAMIENTO]]) -> ASALARIADO | J15: SECTOR PUBLICO | K15: SI | L15: NO | M15: NO | N15: 58 | O15: =IF(moras[[#This Row],[EDAD]]="", '2-Resumen'!$C$7, moras[[#This Row],[EDAD]]) -> 58 | P15: =FLOOR(moras[[#This Row],[EDAD_SIN_NA´S]],10) -> 50 | Q15: =STANDARDIZE(moras[[#This Row],[EDAD]],'2-Resumen'!$C$2, '2-Resumen'!$C$3) -> 1.1358151 | R15: =IF(ABS(moras[[#This Row],[Z-CORE E]]) > 1.96, "Sí", "No") -> No
... A18: 19 | B18: HOMBRE | C18: 553939 | D18: =IF(moras[[#This Row],[SALARIO]] <= '8-Morosidad en númericas'!$C$3, "BAJO", IF(moras[[#This Row],[SALARIO]] <= '8-Morosidad en númericas'!$C$4, "MEDIO-BAJO", IF(moras[[#This Row],[SALARIO]] <='8-Morosidad en númericas'!$C$5, "MEDIO-ALTO", "ALTO"))) -> MEDIO-BAJO | E18: =IF(moras[[#This Row],[SALARIO]]="",'2-Resumen'!$B$7, moras[[#This Row],[SALARIO]]) -> 553939 | F18: =STANDARDIZE(moras[[#This Row],[SALARIO]],'2-Resumen'!$B$2,'2-Resumen'!$B$3) -> -0.36639937 | G18: =IF(ABS(moras[[#This Row],[Z-CORE]])> 1.96,"Sí", "No") -> No | H18: ASALARIADO | I18: =IF(moras[[#This Row],[TIPO_ASEGURAMIENTO]] = "", '2-Resumen'!$F$4, moras[[#This Row],[TIPO_ASEGURAMIENTO]]) -> ASALARIADO | J18: SECTOR PRIVADO | K18: SI | L18: NO | M18: NO | N18: 45 | O18: =IF(moras[[#This Row],[EDAD]]="", '2-Resumen'!$C$7, moras[[#This Row],[EDAD]]) -> 45 | P18: =FLOOR(moras[[#This Row],[EDAD_SIN_NA´S]],10) -> 40 | Q18: =STANDARDIZE(moras[[#This Row],[EDAD]],'2-Resumen'!$C$2, '2-Resumen'!$C$3) -> 0.21833581 | R18: =IF(ABS(moras[[#This Row],[Z-CORE E]]) > 1.96, "Sí", "No") -> No
A19: 21 | B19: MUJER | D19: =IF(moras[[#This Row],[SALARIO]] <= '8-Morosidad en númericas'!$C$3, "BAJO", IF(moras[[#This Row],[SALARIO]] <= '8-Morosidad en númericas'!$C$4, "MEDIO-BAJO", IF(moras[[#This Row],[SALARIO]] <='8-Morosidad en númericas'!$C$5, "MEDIO-ALTO", "ALTO"))) -> BAJO | E19: =IF(moras[[#This Row],[SALARIO]]="",'2-Resumen'!$B$7, moras[[#This Row],[SALARIO]]) -> 639148 | F19: =STANDARDIZE(moras[[#This Row],[SALARIO]],'2-Resumen'!$B$2,'2-Resumen'!$B$3) -> -0.37561638 | G19: =IF(ABS(moras[[#This Row],[Z-CORE]])> 1.96,"Sí", "No") -> No | H19: ASALARIADO | I19: =IF(moras[[#This Row],[TIPO_ASEGURAMIENTO]] = "", '2-Resumen'!$F$4, moras[[#This Row],[TIPO_ASEGURAMIENTO]]) -> ASALARIADO | J19: SECTOR PRIVADO | K19: SI | L19: SI | M19: NO | N19: 28 | O19: =IF(moras[[#This Row],[EDAD]]="", '2-Resumen'!$C$7, moras[[#This Row],[EDAD]]) -> 28 | P19: =FLOOR(moras[[#This Row],[EDAD_SIN_NA´S]],10) -> 20 | Q19: =STANDARDIZE(moras[[#This Row],[EDAD]],'2-Resumen'!$C$2, '2-Resumen'!$C$3) -> -0.9814448 | R19: =IF(ABS(moras[[#This Row],[Z-CORE E]]) > 1.96, "Sí", "No") -> No
A20: 23 | B20: HOMBRE | C20: 2124814 | D20: =IF(moras[[#This Row],[SALARIO]] <= '8-Morosidad en númericas'!$C$3, "BAJO", IF(moras[[#This Row],[SALARIO]] <= '8-Morosidad en númericas'!$C$4, "MEDIO-BAJO", IF(moras[[#This Row],[SALARIO]] <='8-Morosidad en númericas'!$C$5, "MEDIO-ALTO", "ALTO"))) -> MEDIO-ALTO | E20: =IF(moras[[#This Row],[SALARIO]]="",'2-Resumen'!$B$7, moras[[#This Row],[SALARIO]]) -> 2124814 | F20: =STANDARDIZE(moras[[#This Row],[SALARIO]],'2-Resumen'!$B$2,'2-Resumen'!$B$3) -> -0.34026152 | G20: =IF(ABS(moras[[#This Row],[Z-CORE]])> 1.96,"Sí", "No") -> No | H20: ASALARIADO | I20: =IF(moras[[#This Row],[TIPO_ASEGURAMIENTO]] = "", '2-Resumen'!$F$4, moras[[#This Row],[TIPO_ASEGURAMIENTO]]) -> ASALARIADO | J20: SECTOR PRIVADO | K20: SI | L20: NO | M20: NO | N20: 32 | O20: =IF(moras[[#This Row],[EDAD]]="", '2-Resumen'!$C$7, moras[[#This Row],[EDAD]]) -> 32 | P20: =FLOOR(moras[[#This Row],[EDAD_SIN_NA´S]],10) -> 30 | Q20: =STANDARDIZE(moras[[#This Row],[EDAD]],'2-Resumen'!$C$2, '2-Resumen'!$C$3) -> -0.69914348 | R20: =IF(ABS(moras[[#This Row],[Z-CORE E]]) > 1.96, "Sí", "No") -> No
A21: 24 | B21: HOMBRE | C21: 19174468 | D21: =IF(moras[[#This Row],[SALARIO]] <= '8-Morosidad en númericas'!$C$3, "BAJO", IF(moras[[#This Row],[SALARIO]] <= '8-Morosidad en númericas'!$C$4, "MEDIO-BAJO", IF(moras[[#This Row],[SALARIO]] <='8-Morosidad en númericas'!$C$5, "MEDIO-ALTO", "ALTO"))) -> MEDIO-ALTO | E21: =IF(moras[[#This Row],[SALARIO]]="",'2-Resumen'!$B$7, moras[[#This Row],[SALARIO]]) -> 19174468 | F21: =STANDARDIZE(moras[[#This Row],[SALARIO]],'2-Resumen'!$B$2,'2-Resumen'!$B$3) -> -0.056571628 | G21: =IF(ABS(moras[[#This Row],[Z-CORE]])> 1.96,"Sí", "No") -> No | H21: ASALARIADO | I21: =IF(moras[[#This Row],[TIPO_ASEGURAMIENTO]] = "", '2-Resumen'!$F$4, moras[[#This Row],[TIPO_ASEGURAMIENTO]]) -> ASALARIADO | J21: SECTOR PRIVADO | K21: SI | L21: NO | M21: NO | N21: 18 | O21: =IF(moras[[#This Row],[EDAD]]="", '2-Resumen'!$C$7, moras[[#This Row],[EDAD]]) -> 18 | P21: =FLOOR(moras[[#This Row],[EDAD_SIN_NA´S]],10) -> 10 | Q21: =STANDARDIZE(moras[[#This Row],[EDAD]],'2-Resumen'!$C$2, '2-Resumen'!$C$3) -> -1.6871981 | R21: =IF(ABS(moras[[#This Row],[Z-CORE E]]) > 1.96, "Sí", "No") -> No
A22: 25 | B22: MUJER | C22: 1117489 | D22: =IF(moras[[#This Row],[SALARIO]] <= '8-Morosidad en númericas'!$C$3, "BAJO", IF(moras[[#This Row],[SALARIO]] <= '8-Morosidad en númericas'!$C$4, "MEDIO-BAJO", IF(moras[[#This Row],[SALARIO]] <='8-Morosidad en númericas'!$C$5, "MEDIO-ALTO", "ALTO"))) -> MEDIO-ALTO | E22: =IF(moras[[#This Row],[SALARIO]]="",'2-Resumen'!$B$7, moras[[#This Row],[SALARIO]]) -> 1117489 | F22: =STANDARDIZE(moras[[#This Row],[SALARIO]],'2-Resumen'!$B$2,'2-Resumen'!$B$3) -> -0.35702244 | G22: =IF(ABS(moras[[#This Row],[Z-CORE]])> 1.96,"Sí", "No") -> No | H22: ASALARIADO | I22: =IF(moras[[#This Row],[TIPO_ASEGURAMIENTO]] = "", '2-Resumen'!$F$4, moras[[#This Row],[TIPO_ASEGURAMIENTO]]) -> ASALARIADO | J22: SECTOR PUBLICO | K22: SI | L22: NO | M22: SI | N22: 36 | O22: =IF(moras[[#This Row],[EDAD]]="", '2-Resumen'!$C$7, moras[[#This Row],[EDAD]]) -> 36 | P22: =FLOOR(moras[[#This Row],[EDAD_SIN_NA´S]],10) -> 30 | Q22: =STANDARDIZE(moras[[#This Row],[EDAD]],'2-Resumen'!$C$2, '2-Resumen'!$C$3) -> -0.41684216 | R22: =IF(ABS(moras[[#This Row],[Z-CORE E]]) > 1.96, "Sí", "No") -> No
A23: 27 | B23: HOMBRE | C23: 66700 | D23: =IF(moras[[#This Row],[SALARIO]] <= '8-Morosidad en númericas'!$C$3, "BAJO", IF(moras[[#This Row],[SALARIO]] <= '8-Morosidad en númericas'!$C$4, "MEDIO-BAJO", IF(moras[[#This Row],[SALARIO]] <='8-Morosidad en númericas'!$C$5, "MEDIO-ALTO", "ALTO"))) -> BAJO | E23: =IF(moras[[#This Row],[SALARIO]]="",'2-Resumen'!$B$7, moras[[#This Row],[SALARIO]]) -> 66700 | F23: =STANDARDIZE(moras[[#This Row],[SALARIO]],'2-Resumen'!$B$2,'2-Resumen'!$B$3) -> -0.37450656 | G23: =IF(ABS(moras[[#This Row],[Z-CORE]])> 1.96,"Sí", "No") -> No | H23: ASALARIADO | I23: =IF(moras[[#This Row],[TIPO_ASEGURAMIENTO]] = "", '2-Resumen'!$F$4, moras[[#This Row],[TIPO_ASEGURAMIENTO]]) -> ASALARIADO | J23: SECTOR PRIVADO | K23: SI | L23: NO | M23: NO | N23: 38 | O23: =IF(moras[[#This Row],[EDAD]]="", '2-Resumen'!$C$7, moras[[#This Row],[EDAD]]) -> 38 | P23: =FLOOR(moras[[#This Row],[EDAD_SIN_NA´S]],10) -> 30 | Q23: =STANDARDIZE(moras[[#This Row],[EDAD]],'2-Resumen'!$C$2, '2-Resumen'!$C$3) -> -0.2756915 | R23: =IF(ABS(moras[[#This Row],[Z-CORE E]]) > 1.96, "Sí", "No") -> No
A24: 28 | B24: MUJER | C24: 73410 | D24: =IF(moras[[#This Row],[SALARIO]] <= '8-Morosidad en númericas'!$C$3, "BAJO", IF(moras[[#This Row],[SALARIO]] <= '8-Morosidad en númericas'!$C$4, "MEDIO-BAJO", IF(moras[[#This Row],[SALARIO]] <='8-Morosidad en númericas'!$C$5, "MEDIO-ALTO", "ALTO"))) -> BAJO | E24: =IF(moras[[#This Row],[SALARIO]]="",'2-Resumen'!$B$7, moras[[#This Row],[SALARIO]]) -> 73410 | F24: =STANDARDIZE(moras[[#This Row],[SALARIO]],'2-Resumen'!$B$2,'2-Resumen'!$B$3) -> -0.37439491 | G24: =IF(ABS(moras[[#This Row],[Z-CORE]])> 1.96,"Sí", "No") -> No | H24: ASALARIADO | I24: =IF(moras[[#This Row],[TIPO_ASEGURAMIENTO]] = "", '2-Resumen'!$F$4, moras[[#This Row],[TIPO_ASEGURAMIENTO]]) -> ASALARIADO | J24: SECTOR PRIVADO | K24: SI | L24: SI | M24: NO | N24: 22 | O24: =IF(moras[[#This Row],[EDAD]]="", '2-Resumen'!$C$7, moras[[#This Row],[EDAD]]) -> 22 | P24: =FLOOR(moras[[#This Row],[EDAD_SIN_NA´S]],10) -> 20 | Q24: =STANDARDIZE(moras[[#This Row],[EDAD]],'2-Resumen'!$C$2, '2-Resumen'!$C$3) -> -1.4048968 | R24: =IF(ABS(moras[[#This Row],[Z-CORE E]]) > 1.96, "Sí", "No") -> No
A25: 29 | B25: HOMBRE | C25: 81535566 | D25: =IF(moras[[#This Row],[SALARIO]] <= '8-Morosidad en númericas'!$C$3, "BAJO", IF(moras[[#This Row],[SALARIO]] <= '8-Morosidad en númericas'!$C$4, "MEDIO-BAJO", IF(moras[[#This Row],[SALARIO]] <='8-Morosidad en númericas'!$C$5, "MEDIO-ALTO", "ALTO"))) -> ALTO | E25: =IF(moras[[#This Row],[SALARIO]]="",'2-Resumen'!$B$7, moras[[#This Row],[SALARIO]]) -> 81535566 | F25: =STANDARDIZE(moras[[#This Row],[SALARIO]],'2-Resumen'!$B$2,'2-Resumen'!$B$3) -> 0.98105722 | G25: =IF(ABS(moras[[#This Row],[Z-CORE]])> 1.96,"Sí", "No") -> No | H25: ASALARIADO | I25: =IF(moras[[#This Row],[TIPO_ASEGURAMIENTO]] = "", '2-Resumen'!$F$4, moras[[#This Row],[TIPO_ASEGURAMIENTO]]) -> ASALARIADO | J25: SECTOR PUBLICO | K25: SI | L25: NO | M25: NO | N25: 42 | O25: =IF(moras[[#This Row],[EDAD]]="", '2-Resumen'!$C$7, moras[[#This Row],[EDAD]]) -> 42 | P25: =FLOOR(moras[[#This Row],[EDAD_SIN_NA´S]],10) -> 40 | Q25: =STANDARDIZE(moras[[#This Row],[EDAD]],'2-Resumen'!$C$2, '2-Resumen'!$C$3) -> 0.0066098168 | R25: =IF(ABS(moras[[#This Row],[Z-CORE E]]) > 1.96, "Sí", "No") -> No
A26: 30 | B26: HOMBRE | C26: 398125 | D26: =IF(moras[[#This Row],[SALARIO]] <= '8-Morosidad en númericas'!$C$3, "BAJO", IF(moras[[#This Row],[SALARIO]] <= '8-Morosidad en númericas'!$C$4, "MEDIO-BAJO", IF(moras[[#This Row],[SALARIO]] <='8-Morosidad en númericas'!$C$5, "MEDIO-ALTO", "ALTO"))) -> MEDIO-BAJO | E26: =IF(moras[[#This Row],[SALARIO]]="",'2-Resumen'!$B$7, moras[[#This Row],[SALARIO]]) -> 398125 | F26: =STANDARDIZE(moras[[#This Row],[SALARIO]],'2-Resumen'!$B$2,'2-Resumen'!$B$3) -> -0.36899196 | G26: =IF(ABS(moras[[#This Row],[Z-CORE]])> 1.96,"Sí", "No") -> No | H26: ASALARIADO | I26: =IF(moras[[#This Row],[TIPO_ASEGURAMIENTO]] = "", '2-Resumen'!$F$4, moras[[#This Row],[TIPO_ASEGURAMIENTO]]) -> ASALARIADO | J26: SECTOR PRIVADO | K26: SI | L26: NO | M26: NO | N26: 38 | O26: =IF(moras[[#This Row],[EDAD]]="", '2-Resumen'!$C$7, moras[[#This Row],[EDAD]]) -> 38 | P26: =FLOOR(moras[[#This Row],[EDAD_SIN_NA´S]],10) -> 30 | Q26: =STANDARDIZE(moras[[#This Row],[EDAD]],'2-Resumen'!$C$2, '2-Resumen'!$C$3) -> -0.2756915 | R26: =IF(ABS(moras[[#This Row],[Z-CORE E]]) > 1.96, "Sí", "No") -> No
A27: 31 | B27: HOMBRE | C27: 60676396 | D27: =IF(moras[[#This Row],[SALARIO]] <= '8-Morosidad en númericas'!$C$3, "BAJO", IF(moras[[#This Row],[SALARIO]] <= '8-Morosidad en númericas'!$C$4, "MEDIO-BAJO", IF(moras[[#This Row],[SALARIO]] <='8-Morosidad en númericas'!$C$5, "MEDIO-ALTO", "ALTO"))) -> ALTO | E27: =IF(moras[[#This Row],[SALARIO]]="",'2-Resumen'!$B$7, moras[[#This Row],[SALARIO]]) -> 60676396 | F27: =STANDARDIZE(moras[[#This Row],[SALARIO]],'2-Resumen'!$B$2,'2-Resumen'!$B$3) -> 0.63398064 | G27: =IF(ABS(moras[[#This Row],[Z-CORE]])> 1.96,"Sí", "No") -> No | H27: ASALARIADO | I27: =IF(moras[[#This Row],[TIPO_ASEGURAMIENTO]] = "", '2-Resumen'!$F$4, moras[[#This Row],[TIPO_ASEGURAMIENTO]]) -> ASALARIADO | J27: SECTOR PRIVADO | K27: SI | L27: NO | M27: NO | N27: 39 | O27: =IF(moras[[#This Row],[EDAD]]="", '2-Resumen'!$C$7, moras[[#This Row],[EDAD]]) -> 39 | P27: =FLOOR(moras[[#This Row],[EDAD_SIN_NA´S]],10) -> 30 | Q27: =STANDARDIZE(moras[[#This Row],[EDAD]],'2-Resumen'!$C$2, '2-Resumen'!$C$3) -> -0.20511617 | R27: =IF(ABS(moras[[#This Row],[Z-CORE E]]) > 1.96, "Sí", "No") -> No
A28: 33 | B28: MUJER | C28: 297046 | D28: =IF(moras[[#This Row],[SALARIO]] <= '8-Morosidad en númericas'!$C$3, "BAJO", IF(moras[[#This Row],[SALARIO]] <= '8-Morosidad en númericas'!$C$4, "MEDIO-BAJO", IF(moras[[#This Row],[SALARIO]] <='8-Morosidad en númericas'!$C$5, "MEDIO-ALTO", "ALTO"))) -> BAJO | E28: =IF(moras[[#This Row],[SALARIO]]="",'2-Resumen'!$B$7, moras[[#This Row],[SALARIO]]) -> 297046 | F28: =STANDARDIZE(moras[[#This Row],[SALARIO]],'2-Resumen'!$B$2,'2-Resumen'!$B$3) -> -0.37067382 | G28: =IF(ABS(moras[[#This Row],[Z-CORE]])> 1.96,"Sí", "No") -> No | H28: ASALARIADO | I28: =IF(moras[[#This Row],[TIPO_ASEGURAMIENTO]] = "", '2-Resumen'!$F$4, moras[[#This Row],[TIPO_ASEGURAMIENTO]]) -> ASALARIADO | J28: SECTOR PRIVADO | K28: SI | L28: SI | M28: NO | N28: 41 | O28: =IF(moras[[#This Row],[EDAD]]="", '2-Resumen'!$C$7, moras[[#This Row],[EDAD]]) -> 41 | P28: =FLOOR(moras[[#This Row],[EDAD_SIN_NA´S]],10) -> 40 | Q28: =STANDARDIZE(moras[[#This Row],[EDAD]],'2-Resumen'!$C$2, '2-Resumen'!$C$3) -> -0.063965513 | R28: =IF(ABS(moras[[#This Row],[Z-CORE E]]) > 1.96, "Sí", "No") -> No
A29: 34 | B29: HOMBRE | C29: 558030 | D29: =IF(moras[[#This Row],[SALARIO]] <= '8-Morosidad en númericas'!$C$3, "BAJO", IF(moras[[#This Row],[SALARIO]] <= '8-Morosidad en númericas'!$C$4, "MEDIO-BAJO", IF(moras[[#This Row],[SALARIO]] <='8-Morosidad en númericas'!$C$5, "MEDIO-ALTO", "ALTO"))) -> MEDIO-BAJO | E29: =IF(moras[[#This Row],[SALARIO]]="",'2-Resumen'!$B$7, moras[[#This Row],[SALARIO]]) -> 558030 | F29: =STANDARDIZE(moras[[#This Row],[SALARIO]],'2-Resumen'!$B$2,'2-Resumen'!$B$3) -> -0.3663313 | G29: =IF(ABS(moras[[#This Row],[Z-CORE]])> 1.96,"Sí", "No") -> No | H29: ASALARIADO | I29: =IF(moras[[#This Row],[TIPO_ASEGURAMIENTO]] = "", '2-Resumen'!$F$4, moras[[#This Row],[TIPO_ASEGURAMIENTO]]) -> ASALARIADO | J29: SECTOR PRIVADO | K29: SI | L29: NO | M29: NO | N29: 28 | O29: =IF(moras[[#This Row],[EDAD]]="", '2-Resumen'!$C$7, moras[[#This Row],[EDAD]]) -> 28 | P29: =FLOOR(moras[[#This Row],[EDAD_SIN_NA´S]],10) -> 20 | Q29: =STANDARDIZE(moras[[#This Row],[EDAD]],'2-Resumen'!$C$2, '2-Resumen'!$C$3) -> -0.9814448 | R29: =IF(ABS(moras[[#This Row],[Z-CORE E]]) > 1.96, "Sí", "No") -> No
A30: 35 | B30: HOMBRE | C30: 6830903 | D30: =IF(moras[[#This Row],[SALARIO]] <= '8-Morosidad en númericas'!$C$3, "BAJO", IF(moras[[#This Row],[SALARIO]] <= '8-Morosidad en númericas'!$C$4, "MEDIO-BAJO", IF(moras[[#This Row],[SALARIO]] <='8-Morosidad en númericas'!$C$5, "MEDIO-ALTO", "ALTO"))) -> MEDIO-ALTO | E30: =IF(moras[[#This Row],[SALARIO]]="",'2-Resumen'!$B$7, moras[[#This Row],[SALARIO]]) -> 6830903 | F30: =STANDARDIZE(moras[[#This Row],[SALARIO]],'2-Resumen'!$B$2,'2-Resumen'!$B$3) -> -0.26195671 | G30: =IF(ABS(moras[[#This Row],[Z-CORE]])> 1.96,"Sí", "No") -> No | H30: ASALARIADO | I30: =IF(moras[[#This Row],[TIPO_ASEGURAMIENTO]] = "", '2-Resumen'!$F$4, moras[[#This Row],[TIPO_ASEGURAMIENTO]]) -> ASALARIADO | J30: SECTOR PRIVADO | K30: SI | L30: NO | M30: NO | N30: 43 | O30: =IF(moras[[#This Row],[EDAD]]="", '2-Resumen'!$C$7, moras[[#This Row],[EDAD]]) -> 43 | P30: =FLOOR(moras[[#This Row],[EDAD_SIN_NA´S]],10) -> 40 | Q30: =STANDARDIZE(moras[[#This Row],[EDAD]],'2-Resumen'!$C$2, '2-Resumen'!$C$3) -> 0.077185147 | R30: =IF(ABS(moras[[#This Row],[Z-CORE E]]) > 1.96, "Sí", "No") -> No
A31: 36 | B31: HOMBRE | D31: =IF(moras[[#This Row],[SALARIO]] <= '8-Morosidad en númericas'!$C$3, "BAJO", IF(moras[[#This Row],[SALARIO]] <= '8-Morosidad en númericas'!$C$4, "MEDIO-BAJO", IF(moras[[#This Row],[SALARIO]] <='8-Morosidad en númericas'!$C$5, "MEDIO-ALTO", "ALTO"))) -> BAJO | E31: =IF(moras[[#This Row],[SALARIO]]="",'2-Resumen'!$B$7, moras[[#This Row],[SALARIO]]) -> 639148 | F31: =STANDARDIZE(moras[[#This Row],[SALARIO]],'2-Resumen'!$B$2,'2-Resumen'!$B$3) -> -0.37561638 | G31: =IF(ABS(moras[[#This Row],[Z-CORE]])> 1.96,"Sí", "No") -> No | H31: ASALARIADO | I31: =IF(moras[[#This Row],[TIPO_ASEGURAMIENTO]] = "", '2-Resumen'!$F$4, moras[[#This Row],[TIPO_ASEGURAMIENTO]]) -> ASALARIADO | J31: SECTOR PUBLICO | K31: SI | L31: NO | M31: NO | N31: 62 | O31: =IF(moras[[#This Row],[EDAD]]="", '2-Resumen'!$C$7, moras[[#This Row],[EDAD]]) -> 62 | P31: =FLOOR(moras[[#This Row],[EDAD_SIN_NA´S]],10) -> 60 | Q31: =STANDARDIZE(moras[[#This Row],[EDAD]],'2-Resumen'!$C$2, '2-Resumen'!$C$3) -> 1.4181164 | R31: =IF(ABS(moras[[#This Row],[Z-CORE E]]) > 1.96, "Sí", "No") -> No
A32: 37 | B32: HOMBRE | C32: 15523075 | D32: =IF(moras[[#This Row],[SALARIO]] <= '8-Morosidad en númericas'!$C$3, "BAJO", IF(moras[[#This Row],[SALARIO]] <= '8-Morosidad en númericas'!$C$4, "MEDIO-BAJO", IF(moras[[#This Row],[SALARIO]] <='8-Morosidad en númericas'!$C$5, "MEDIO-ALTO", "ALTO"))) -> MEDIO-ALTO | E32: =IF(moras[[#This Row],[SALARIO]]="",'2-Resumen'!$B$7, moras[[#This Row],[SALARIO]]) -> 15523075 | F32: =STANDARDIZE(moras[[#This Row],[SALARIO]],'2-Resumen'!$B$2,'2-Resumen'!$B$3) -> -0.1173273 | G32: =IF(ABS(moras[[#This Row],[Z-CORE]])> 1.96,"Sí", "No") -> No | H32: ASALARIADO | I32: =IF(moras[[#This Row],[TIPO_ASEGURAMIENTO]] = "", '2-Resumen'!$F$4, moras[[#This Row],[TIPO_ASEGURAMIENTO]]) -> ASALARIADO | J32: SECTOR PRIVADO | K32: SI | L32: SI | M32: NO | N32: 41 | O32: =IF(moras[[#This Row],[EDAD]]="", '2-Resumen'!$C$7, moras[[#This Row],[EDAD]]) -> 41 | P32: =FLOOR(moras[[#This Row],[EDAD_SIN_NA´S]],10) -> 40 | Q32: =STANDARDIZE(moras[[#This Row],[EDAD]],'2-Resumen'!$C$2, '2-Resumen'!$C$3) -> -0.063965513 | R32: =IF(ABS(moras[[#This Row],[Z-CORE E]]) > 1.96, "Sí", "No") -> No
A33: 39 | B33: HOMBRE | C33: 322056909 | D33: =IF(moras[[#This Row],[SALARIO]] <= '8-Morosidad en númericas'!$C$3, "BAJO", IF(moras[[#This Row],[SALARIO]] <= '8-Morosidad en númericas'!$C$4, "MEDIO-BAJO", IF(moras[[#This Row],[SALARIO]] <='8-Morosidad en númericas'!$C$5, "MEDIO-ALTO", "ALTO"))) -> ALTO | E33: =IF(moras[[#This Row],[SALARIO]]="",'2-Resumen'!$B$7, moras[[#This Row],[SALARIO]]) -> 322056909 | F33: =STANDARDIZE(moras[[#This Row],[SALARIO]],'2-Resumen'!$B$2,'2-Resumen'!$B$3) -> 4.9831017 | G33: =IF(ABS(moras[[#This Row],[Z-CORE]])> 1.96,"Sí", "No") -> Sí | H33: ASALARIADO | I33: =IF(moras[[#This Row],[TIPO_ASEGURAMIENTO]] = "", '2-Resumen'!$F$4, moras[[#This Row],[TIPO_ASEGURAMIENTO]]) -> ASALARIADO | J33: SECTOR PRIVADO | K33: SI | L33: NO | M33: NO | N33: 48 | O33: =IF(moras[[#This Row],[EDAD]]="", '2-Resumen'!$C$7, moras[[#This Row],[EDAD]]) -> 48 | P33: =FLOOR(moras[[#This Row],[EDAD_SIN_NA´S]],10) -> 40 | Q33: =STANDARDIZE(moras[[#This Row],[EDAD]],'2-Resumen'!$C$2, '2-Resumen'!$C$3) -> 0.4300618 | R33: =IF(ABS(moras[[#This Row],[Z-CORE E]]) > 1.96, "Sí", "No") -> No
A34: 40 | B34: HOMBRE | C34: 658917 | D34: =IF(moras[[#This Row],[SALARIO]] <= '8-Morosidad en númericas'!$C$3, "BAJO", IF(moras[[#This Row],[SALARIO]] <= '8-Morosidad en númericas'!$C$4, "MEDIO-BAJO", IF(moras[[#This Row],[SALARIO]] <='8-Morosidad en númericas'!$C$5, "MEDIO-ALTO", "ALTO"))) -> MEDIO-ALTO | E34: =IF(moras[[#This Row],[SALARIO]]="",'2-Resumen'!$B$7, moras[[#This Row],[SALARIO]]) -> 658917 | F34: =STANDARDIZE(moras[[#This Row],[SALARIO]],'2-Resumen'!$B$2,'2-Resumen'!$B$3) -> -0.36465264 | G34: =IF(ABS(moras[[#This Row],[Z-CORE]])> 1.96,"Sí", "No") -> No | H34: ASALARIADO | I34: =IF(moras[[#This Row],[TIPO_ASEGURAMIENTO]] = "", '2-Resumen'!$F$4, moras[[#This Row],[TIPO_ASEGURAMIENTO]]) -> ASALARIADO | J34: SECTOR PUBLICO | K34: SI | L34: NO | M34: SI | N34: 56 | O34: =IF(moras[[#This Row],[EDAD]]="", '2-Resumen'!$C$7, moras[[#This Row],[EDAD]]) -> 56 | P34: =FLOOR(moras[[#This Row],[EDAD_SIN_NA´S]],10) -> 50 | Q34: =STANDARDIZE(moras[[#This Row],[EDAD]],'2-Resumen'!$C$2, '2-Resumen'!$C$3) -> 0.99466444 | R34: =IF(ABS(moras[[#This Row],[Z-CORE E]]) > 1.96, "Sí", "No") -> No
A35: 41 | B35: HOMBRE | C35: 6317076 | D35: =IF(moras[[#This Row],[SALARIO]] <= '8-Morosidad en númericas'!$C$3, "BAJO", IF(moras[[#This Row],[SALARIO]] <= '8-Morosidad en númericas'!$C$4, "MEDIO-BAJO", IF(moras[[#This Row],[SALARIO]] <='8-Morosidad en númericas'!$C$5, "MEDIO-ALTO", "ALTO"))) -> MEDIO-ALTO | E35: =IF(moras[[#This Row],[SALARIO]]="",'2-Resumen'!$B$7, moras[[#This Row],[SALARIO]]) -> 6317076 | F35: =STANDARDIZE(moras[[#This Row],[SALARIO]],'2-Resumen'!$B$2,'2-Resumen'!$B$3) -> -0.2705063 | G35: =IF(ABS(moras[[#This Row],[Z-CORE]])> 1.96,"Sí", "No") -> No | H35: ASALARIADO | I35: =IF(moras[[#This Row],[TIPO_ASEGURAMIENTO]] = "", '2-Resumen'!$F$4, moras[[#This Row],[TIPO_ASEGURAMIENTO]]) -> ASALARIADO | J35: SECTOR PRIVADO | K35: SI | L35: NO | M35: NO | N35: 25 | O35: =IF(moras[[#This Row],[EDAD]]="", '2-Resumen'!$C$7, moras[[#This Row],[EDAD]]) -> 25 | P35: =FLOOR(moras[[#This Row],[EDAD_SIN_NA´S]],10) -> 20 | Q35: =STANDARDIZE(moras[[#This Row],[EDAD]],'2-Resumen'!$C$2, '2-Resumen'!$C$3) -> -1.1931708 | R35: =IF(ABS(moras[[#This Row],[Z-CORE E]]) > 1.96, "Sí", "No") -> No
A36: 42 | B36: MUJER | C36: 977376 | D36: =IF(moras[[#This Row],[SALARIO]] <= '8-Morosidad en númericas'!$C$3, "BAJO", IF(moras[[#This Row],[SALARIO]] <= '8-Morosidad en númericas'!$C$4, "MEDIO-BAJO", IF(moras[[#This Row],[SALARIO]] <='8-Morosidad en númericas'!$C$5, "MEDIO-ALTO", "ALTO"))) -> MEDIO-ALTO | E36: =IF(moras[[#This Row],[SALARIO]]="",'2-Resumen'!$B$7, moras[[#This Row],[SALARIO]]) -> 977376 | F36: =STANDARDIZE(moras[[#This Row],[SALARIO]],'2-Resumen'!$B$2,'2-Resumen'!$B$3) -> -0.35935378 | G36: =IF(ABS(moras[[#This Row],[Z-CORE]])> 1.96,"Sí", "No") -> No | H36: ASALARIADO | I36: =IF(moras[[#This Row],[TIPO_ASEGURAMIENTO]] = "", '2-Resumen'!$F$4, moras[[#This Row],[TIPO_ASEGURAMIENTO]]) -> ASALARIADO | J36: SECTOR PRIVADO | K36: SI | L36: NO | M36: NO | N36: 33 | O36: =IF(moras[[#This Row],[EDAD]]="", '2-Resumen'!$C$7, moras[[#This Row],[EDAD]]) -> 33 | P36: =FLOOR(moras[[#This Row],[EDAD_SIN_NA´S]],10) -> 30 | Q36: =STANDARDIZE(moras[[#This Row],[EDAD]],'2-Resumen'!$C$2, '2-Resumen'!$C$3) -> -0.62856815 | R36: =IF(ABS(moras[[#This Row],[Z-CORE E]]) > 1.96, "Sí", "No") -> No
A37: 44 | B37: HOMBRE | C37: 633750 | D37: =IF(moras[[#This Row],[SALARIO]] <= '8-Morosidad en númericas'!$C$3, "BAJO", IF(moras[[#This Row],[SALARIO]] <= '8-Morosidad en númericas'!$C$4, "MEDIO-BAJO", IF(moras[[#This Row],[SALARIO]] <='8-Morosidad en númericas'!$C$5, "MEDIO-ALTO", "ALTO"))) -> MEDIO-BAJO | E37: =IF(moras[[#This Row],[SALARIO]]="",'2-Resumen'!$B$7, moras[[#This Row],[SALARIO]]) -> 633750 | F37: =STANDARDIZE(moras[[#This Row],[SALARIO]],'2-Resumen'!$B$2,'2-Resumen'!$B$3) -> -0.36507139 | G37: =IF(ABS(moras[[#This Row],[Z-CORE]])> 1.96,"Sí", "No") -> No | H37: ASALARIADO | I37: =IF(moras[[#This Row],[TIPO_ASEGURAMIENTO]] = "", '2-Resumen'!$F$4, moras[[#This Row],[TIPO_ASEGURAMIENTO]]) -> ASALARIADO | J37: SECTOR PRIVADO | K37: SI | L37: NO | M37: NO | N37: 43 | O37: =IF(moras[[#This Row],[EDAD]]="", '2-Resumen'!$C$7, moras[[#This Row],[EDAD]]) -> 43 | P37: =FLOOR(moras[[#This Row],[EDAD_SIN_NA´S]],10) -> 40 | Q37: =STANDARDIZE(moras[[#This Row],[EDAD]],'2-Resumen'!$C$2, '2-Resumen'!$C$3) -> 0.077185147 | R37: =IF(ABS(moras[[#This Row],[Z-CORE E]]) > 1.96, "Sí", "No") -> No
A38: 45 | B38: MUJER | C38: 376776 | D38: =IF(moras[[#This Row],[SALARIO]] <= '8-Morosidad en númericas'!$C$3, "BAJO", IF(moras[[#This Row],[SALARIO]] <= '8-Morosidad en númericas'!$C$4, "MEDIO-BAJO", IF(moras[[#This Row],[SALARIO]] <='8-Morosidad en númericas'!$C$5, "MEDIO-ALTO", "ALTO"))) -> MEDIO-BAJO | E38: =IF(moras[[#This Row],[SALARIO]]="",'2-Resumen'!$B$7, moras[[#This Row],[SALARIO]]) -> 376776 | F38: =STANDARDIZE(moras[[#This Row],[SALARIO]],'2-Resumen'!$B$2,'2-Resumen'!$B$3) -> -0.36934719 | G38: =IF(ABS(moras[[#This Row],[Z-CORE]])> 1.96,"Sí", "No") -> No | H38: ASALARIADO | I38: =IF(moras[[#This Row],[TIPO_ASEGURAMIENTO]] = "", '2-Resumen'!$F$4, moras[[#This Row],[TIPO_ASEGURAMIENTO]]) -> ASALARIADO | J38: SECTOR PRIVADO | K38: SI | L38: NO | M38: NO | N38: 27 | O38: =IF(moras[[#This Row],[EDAD]]="", '2-Resumen'!$C$7, moras[[#This Row],[EDAD]]) -> 27 | P38: =FLOOR(moras[[#This Row],[EDAD_SIN_NA´S]],10) -> 20 | Q38: =STANDARDIZE(moras[[#This Row],[EDAD]],'2-Resumen'!$C$2, '2-Resumen'!$C$3) -> -1.0520201 | R38: =IF(ABS(moras[[#This Row],[Z-CORE E]]) > 1.96, "Sí", "No") -> No
A39: 46 | B39: MUJER | C39: 187838622 | D39: =IF(moras[[#This Row],[SALARIO]] <= '8-Morosidad en númericas'!$C$3, "BAJO", IF(moras[[#This Row],[SALARIO]] <= '8-Morosidad en númericas'!$C$4, "MEDIO-BAJO", IF(moras[[#This Row],[SALARIO]] <='8-Morosidad en númericas'!$C$5, "MEDIO-ALTO", "ALTO"))) -> ALTO | E39: =IF(moras[[#This Row],[SALARIO]]="",'2-Resumen'!$B$7, moras[[#This Row],[SALARIO]]) -> 187838622 | F39: =STANDARDIZE(moras[[#This Row],[SALARIO]],'2-Resumen'!$B$2,'2-Resumen'!$B$3) -> 2.7498381 | G39: =IF(ABS(moras[[#This Row],[Z-CORE]])> 1.96,"Sí", "No") -> Sí | H39: ASALARIADO | I39: =IF(moras[[#This Row],[TIPO_ASEGURAMIENTO]] = "", '2-Resumen'!$F$4, moras[[#This Row],[TIPO_ASEGURAMIENTO]]) -> ASALARIADO | J39: SECTOR PRIVADO | K39: SI | L39: NO | M39: NO | N39: 28 | O39: =IF(moras[[#This Row],[EDAD]]="", '2-Resumen'!$C$7, moras[[#This Row],[EDAD]]) -> 28 | P39: =FLOOR(moras[[#This Row],[EDAD_SIN_NA´S]],10) -> 20 | Q39: =STANDARDIZE(moras[[#This Row],[EDAD]],'2-Resumen'!$C$2, '2-Resumen'!$C$3) -> -0.9814448 | R39: =IF(ABS(moras[[#This Row],[Z-CORE E]]) > 1.96, "Sí", "No") -> No
A40: 47 | B40: MUJER | C40: 2224883 | D40: =IF(moras[[#This Row],[SALARIO]] <= '8-Morosidad en númericas'!$C$3, "BAJO", IF(moras[[#This Row],[SALARIO]] <= '8-Morosidad en númericas'!$C$4, "MEDIO-BAJO", IF(moras[[#This Row],[SALARIO]] <='8-Morosidad en númericas'!$C$5, "MEDIO-ALTO", "ALTO"))) -> MEDIO-ALTO | E40: =IF(moras[[#This Row],[SALARIO]]="",'2-Resumen'!$B$7, moras[[#This Row],[SALARIO]]) -> 2224883 | F40: =STANDARDIZE(moras[[#This Row],[SALARIO]],'2-Resumen'!$B$2,'2-Resumen'!$B$3) -> -0.33859646 | G40: =IF(ABS(moras[[#This Row],[Z-CORE]])> 1.96,"Sí", "No") -> No | H40: ASALARIADO | I40: =IF(moras[[#This Row],[TIPO_ASEGURAMIENTO]] = "", '2-Resumen'!$F$4, moras[[#This Row],[TIPO_ASEGURAMIENTO]]) -> ASALARIADO | J40: SECTOR PRIVADO | K40: SI | L40: NO | M40: NO | N40: 49 | O40: =IF(moras[[#This Row],[EDAD]]="", '2-Resumen'!$C$7, moras[[#This Row],[EDAD]]) -> 49 | P40: =FLOOR(moras[[#This Row],[EDAD_SIN_NA´S]],10) -> 40 | Q40: =STANDARDIZE(moras[[#This Row],[EDAD]],'2-Resumen'!$C$2, '2-Resumen'!$C$3) -> 0.50063713 | R40: =IF(ABS(moras[[#This Row],[Z-CORE E]]) > 1.96, "Sí", "No") -> No
A41: 48 | B41: MUJER | C41: 349000 | D41: =IF(moras[[#This Row],[SALARIO]] <= '8-Morosidad en númericas'!$C$3, "BAJO", IF(moras[[#This Row],[SALARIO]] <= '8-Morosidad en númericas'!$C$4, "MEDIO-BAJO", IF(moras[[#This Row],[SALARIO]] <='8-Morosidad en númericas'!$C$5, "MEDIO-ALTO", "ALTO"))) -> MEDIO-BAJO | E41: =IF(moras[[#This Row],[SALARIO]]="",'2-Resumen'!$B$7, moras[[#This Row],[SALARIO]]) -> 349000 | F41: =STANDARDIZE(moras[[#This Row],[SALARIO]],'2-Resumen'!$B$2,'2-Resumen'!$B$3) -> -0.36980936 | G41: =IF(ABS(moras[[#This Row],[Z-CORE]])> 1.96,"Sí", "No") -> No | H41: ASALARIADO | I41: =IF(moras[[#This Row],[TIPO_ASEGURAMIENTO]] = "", '2-Resumen'!$F$4, moras[[#This Row],[TIPO_ASEGURAMIENTO]]) -> ASALARIADO | J41: SECTOR PRIVADO | K41: SI | L41: NO | M41: NO | N41: 36 | O41: =IF(moras[[#This Row],[EDAD]]="", '2-Resumen'!$C$7, moras[[#This Row],[EDAD]]) -> 36 | P41: =FLOOR(moras[[#This Row],[EDAD_SIN_NA´S]],10) -> 30 | Q41: =STANDARDIZE(moras[[#This Row],[EDAD]],'2-Resumen'!$C$2, '2-Resumen'!$C$3) -> -0.41684216 | R41: =IF(ABS(moras[[#This Row],[Z-CORE E]]) > 1.96, "Sí", "No") -> No
A42: 49 | B42: HOMBRE | C42: 67506969 | D42: =IF(moras[[#This Row],[SALARIO]] <= '8-Morosidad en númericas'!$C$3, "BAJO", IF(moras[[#This Row],[SALARIO]] <= '8-Morosidad en númericas'!$C$4, "MEDIO-BAJO", IF(moras[[#This Row],[SALARIO]] <='8-Morosidad en númericas'!$C$5, "MEDIO-ALTO", "ALTO"))) -> ALTO | E42: =IF(moras[[#This Row],[SALARIO]]="",'2-Resumen'!$B$7, moras[[#This Row],[SALARIO]]) -> 67506969 | F42: =STANDARDIZE(moras[[#This Row],[SALARIO]],'2-Resumen'!$B$2,'2-Resumen'!$B$3) -> 0.74763483 | G42: =IF(ABS(moras[[#This Row],[Z-CORE]])> 1.96,"Sí", "No") -> No | H42: ASALARIADO | I42: =IF(moras[[#This Row],[TIPO_ASEGURAMIENTO]] = "", '2-Resumen'!$F$4, moras[[#This Row],[TIPO_ASEGURAMIENTO]]) -> ASALARIADO | J42: SECTOR PRIVADO | K42: SI | L42: NO | M42: NO | N42: 39 | O42: =IF(moras[[#This Row],[EDAD]]="", '2-Resumen'!$C$7, moras[[#This Row],[EDAD]]) -> 39 | P42: =FLOOR(moras[[#This Row],[EDAD_SIN_NA´S]],10) -> 30 | Q42: =STANDARDIZE(moras[[#This Row],[EDAD]],'2-Resumen'!$C$2, '2-Resumen'!$C$3) -> -0.20511617 | R42: =IF(ABS(moras[[#This Row],[Z-CORE E]]) > 1.96, "Sí", "No") -> No
...

Sheet 4-Valores Faltantes
B1: Cantidad de valores faltantes | C1: Total de valores | D1: Porcentaje de NA´s
A2: IDENTIFICACION | B2: =COUNTBLANK(moras[IDENTIFICACION]) -> 0 | C2: =COUNT(moras!A:A) -> 5000 | D2: =B2/C2 -> 0
A3: SEXO | B3: =COUNTBLANK(moras[SEXO]) -> 0 | C3: =COUNT(moras!A:A) -> 5000 | D3: =B3/C3 -> 0
A4: SALARIO | B4: =COUNTBLANK(moras[SALARIO]) -> 3 | C4: =COUNT(moras!A:A) -> 5000 | D4: =B4/C4 -> 0.0006
A5: Z-CORE | B5: =COUNTBLANK(moras[Z-CORE]) -> 0 | C5: =COUNT(moras!A:A) -> 5000 | D5: =B5/C5 -> 0
A6: INDICADOR_VALOR_ATÍPICO_SALARIO | B6: =COUNTBLANK(moras[INDICADOR_VALOR_ATÍPICO_SALARIO]) -> 0 | C6: =COUNT(moras!A:A) -> 5000 | D6: =B6/C6 -> 0
A7: TIPO_ASEGURAMIENTO | B7: =COUNTBLANK(moras[TIPO_ASEGURAMIENTO]) -> 2 | C7: =COUNT(moras!A:A) -> 5000 | D7: =B7/C7 -> 0.0004
A8: SECTOR | B8: =COUNTBLANK(moras[SECTOR]) -> 0 | C8: =COUNT(moras!A:A) -> 5000 | D8: =B8/C8 -> 0
A9: INDICADOR_ACTIVO | B9: =COUNTBLANK(moras[INDICADOR_ACTIVO]) -> 0 | C9: =COUNT(moras!A:A) -> 5000 | D9: =B9/C9 -> 0
A10: INDICADOR.EXTRANJERO | B10: =COUNTBLANK(moras[INDICADOR.EXTRANJERO]) -> 0 | C10: =COUNT(moras!A:A) -> 5000 | D10: =B10/C10 -> 0
A11: INDICADOR_MOROSO | B11: =COUNTBLANK(moras[INDICADOR_MOROSO]) -> 0 | C11: =COUNT(moras!A:A) -> 5000 | D11: =B11/C11 -> 0
A12: EDAD | B12: =COUNTBLANK(moras[EDAD]) -> 3 | C12: =COUNT(moras!A:A) -> 5000 | D12: =B12/C12 -> 0.0006
A13: Z-CORE E | B13: =COUNTBLANK(moras[Z-CORE E]) -> 0 | C13: =COUNT(moras!A:A) -> 5000 | D13: =B13/C13 -> 0
A14: INDICADOR_VALOR_ATÍPICO_EDAD | B14: =COUNTBLANK(moras[INDICADOR_VALOR_ATÍPICO_EDAD]) -> 0 | C14: =COUNT(moras!A:A) -> 5000 | D14: =B14/C14 -> 0

Sheet 6-Individuos por categoría
B2: Sexo | C2: Frecuencia observada
B3: Hombre | C3: =COUNTIF(moras[SEXO], "HOMBRE") -> 3012
B4: Mujer | C4: =COUNTIF(moras[SEXO], "MUJER") -> 1988
B6: Indicador Activo | C6: Frecuencia observada
B7: Si | C7: =COUNTIF(moras[INDICADOR_ACTIVO], "SI") -> 4966
B8: No | C8: =COUNTIF(moras[INDICADOR_ACTIVO], "NO") -> 34
B10: Indicador Extranjero | C10: Frecuencia observada
B11: Si | C11: =COUNTIF(moras[INDICADOR.EXTRANJERO], "SI") -> 603
B12: No | C12: =COUNTIF(moras[INDICADOR.EXTRANJERO], "NO") -> 4397
B14: Indicador Moroso | C14: Frecuencia observada
B15: Si | C15: =COUNTIF(moras[INDICADOR_MOROSO], "SI") -> 870
B16: No | C16: =COUNTIF(moras[INDICADOR_MOROSO], "NO") -> 4130
B18: Tipo Aseguramiento | C18: Frecuencia observada
B19: Asalariado | C19: =COUNTIF(moras[TIPO_ASEGURAMIENTO_SIN_NA´S], "ASALARIADO") -> 3464
B20: Asegurado Voluntario | C20: =COUNTIF(moras[TIPO_ASEGURAMIENTO_SIN_NA´S], "ASEGURADO VOLUNTARIO") -> 436
B21: Pensionados en su propio sistema | C21: =COUNTIF(moras[TIPO_ASEGURAMIENTO_SIN_NA´S], "PENSIONADOS EN SU PROPIO SISTEMA") -> 212
B22: Trabajador independiente | C22: =COUNTIF(moras[TIPO_ASEGURAMIENTO_SIN_NA´S], "TRABAJADOR INDEPENDIENTE") -> 700
B23: CE de Asegurados Voluntarios | C23: =COUNTIF(moras[TIPO_ASEGURAMIENTO_SIN_NA´S], "CONVENIOS ESPECIALES DE ASEGURADOS VOLUNTARIOS") -> 31
B24: CE de Trabajadores Independientes | C24: =COUNTIF(moras[TIPO_ASEGURAMIENTO_SIN_NA´S], "CONVENIOS ESPECIALES DE TRABAJADORES INDEPENDIENTES") -> 157
B26: Sector | C26: Frecuencia observada
B27: Sector privado | C27: =COUNTIF(moras[SECTOR], "SECTOR PRIVADO") -> 3906
B28: Sector público | C28: =COUNTIF(moras[SECTOR], "SECTOR PUBLICO") -> 1094

Sheet 7-Porcentaje Personas Morosas
B2: Sexo | C2: Porcentaje morosidad
B3: Hombre | C3: =COUNTIFS(moras[SEXO], "HOMBRE", moras[INDICADOR_MOROSO], "SI")/COUNTIF(moras[SEXO], "HOMBRE") -> 0.17729084
B4: Mujer | C4: =COUNTIFS(moras[SEXO], "MUJER", moras[INDICADOR_MOROSO], "SI")/COUNTIF(moras[SEXO], "MUJER") -> 0.16901408
B6: Indicador Activo | C6: Porcentaje morosidad
B7: Si | C7: =COUNTIFS(moras[INDICADOR_ACTIVO], "SI", moras[INDICADOR_MOROSO], "SI")/COUNTIF(moras[INDICADOR_ACTIVO], "SI") -> 0.17156665
B8: No | C8: =COUNTIFS(moras[INDICADOR_ACTIVO], "NO", moras[INDICADOR_MOROSO], "SI")/COUNTIF(moras[INDICADOR_ACTIVO], "NO") -> 0.52941176
B10: Indicador Extranjero | C10: Porcentaje morosidad
B11: Si | C11: =COUNTIFS(moras[INDICADOR.EXTRANJERO], "SI", moras[INDICADOR_MOROSO], "SI")/COUNTIF(moras[INDICADOR.EXTRANJERO], "SI") -> 0.24046434
B12: No | C12: =COUNTIFS(moras[INDICADOR.EXTRANJERO], "NO", moras[INDICADOR_MOROSO], "SI")/COUNTIF(moras[INDICADOR.EXTRANJERO], "NO") -> 0.16488515
B14: Tipo Aseguramiento | C14: Porcentaje morosidad
B15: Asalariado | C15: =COUNTIFS(moras[TIPO_ASEGURAMIENTO_SIN_NA´S], "ASALARIADO", moras[INDICADOR_MOROSO], "SI")/COUNTIF(moras[TIPO_ASEGURAMIENTO_SIN_NA´S], "ASALARIADO") -> 0.1198037
B16: Asegurado Voluntario | C16: =COUNTIFS(moras[TIPO_ASEGURAMIENTO_SIN_NA´S], "ASEGURADO VOLUNTARIO", moras[INDICADOR_MOROSO], "SI")/COUNTIF(moras[TIPO_ASEGURAMIENTO_SIN_NA´S], "ASEGURADO VOLUNTARIO") -> 0.13302752
B17: Pensionados en su propio sistema | C17: =COUNTIFS(moras[TIPO_ASEGURAMIENTO_SIN_NA´S], "PENSIONADOS EN SU PROPIO SISTEMA", moras[INDICADOR_MOROSO], "SI")/COUNTIF(moras[TIPO_ASEGURAMIENTO_SIN_NA´S], "PENSIONADOS EN SU PROPIO SISTEMA") -> 0
B18: Trabajador independiente | C18: =COUNTIFS(moras[TIPO_ASEGURAMIENTO_SIN_NA´S], "TRABAJADOR INDEPENDIENTE", moras[INDICADOR_MOROSO], "SI")/COUNTIF(moras[TIPO_ASEGURAMIENTO_SIN_NA´S], "TRABAJADOR INDEPENDIENTE") -> 0.56142857
B19: CE de Asegurados Voluntarios | C19: =COUNTIFS(moras[TIPO_ASEGURAMIENTO_SIN_NA´S], "CONVENIOS ESPECIALES DE ASEGURADOS VOLUNTARIOS", moras[INDICADOR_MOROSO], "SI")/COUNTIF(moras[TIPO_ASEGURAMIENTO_SIN_NA´S], "CONVENIOS ESPECIALES DE ASEGURADOS VOLUNTARIOS") -> 0
B20: CE de Trabajadores Independientes | C20: =COUNTIFS(moras[TIPO_ASEGURAMIENTO_SIN_NA´S], "CONVENIOS ESPECIALES DE TRABAJADORES INDEPENDIENTES", moras[INDICADOR_MOROSO], "SI")/COUNTIF(moras[TIPO_ASEGURAMIENTO_SIN_NA´S], "CONVENIOS ESPECIALES DE TRABAJADORES INDEPENDIENTES") -> 0.025477707
B22: Sector | C22: Porcentaje morosidad
B23: Sector privado | C23: =COUNTIFS(moras[SECTOR], "SECTOR PRIVADO", moras[INDICADOR_MOROSO], "SI")/COUNTIF(moras[SECTOR], "SECTOR PRIVADO") -> 0.18023554
B24: Sector público | C24: =COUNTIFS(moras[SECTOR], "SECTOR PUBLICO", moras[INDICADOR_MOROSO], "SI")/COUNTIF(moras[SECTOR], "SECTOR PUBLICO") -> 0.15173675

Sheet 8-Morosidad en númericas
C2: Salario
B3: Q1 | C3: =PERCENTILE(moras[SALARIO SIN NA´S], 0.25) -> 310124
B4: Q2 | C4: =PERCENTILE(moras[SALARIO SIN NA´S], 0.5) -> 639148
B5: Q3 | C5: =PERCENTILE(moras[SALARIO SIN NA´S], 0.75) -> 23216469
B7: Salario | C7: Morosidad | D7: Sin Morosidad
B8: Bajo | C8: =COUNTIFS(moras[SALARIO_GRUPO], "BAJO", moras[INDICADOR_MOROSO], "SI") -> 288 | D8: =COUNTIFS(moras[SALARIO_GRUPO], "Bajo", moras[INDICADOR_MOROSO], "NO") -> 976
B9: Medio-Bajo | C9: =COUNTIFS(moras[SALARIO_GRUPO], "MEDIO-BAJO", moras[INDICADOR_MOROSO], "SI") -> 393 | D9: =COUNTIFS(moras[SALARIO_GRUPO], "MEDIO-BAJO", moras[INDICADOR_MOROSO], "NO") -> 888
B10: Medio-Alto | C10: =COUNTIFS(moras[SALARIO_GRUPO], "MEDIO-ALTO", moras[INDICADOR_MOROSO], "SI") -> 155 | D10: =COUNTIFS(moras[SALARIO_GRUPO], "MEDIO-ALTO", moras[INDICADOR_MOROSO], "NO") -> 1050
B11: Alto | C11: =COUNTIFS(moras[SALARIO_GRUPO], "ALTO", moras[INDICADOR_MOROSO], "SI") -> 34 | D11: =COUNTIFS(moras[SALARIO_GRUPO], "ALTO", moras[INDICADOR_MOROSO], "NO") -> 1216
B14: Edad | C14: Morosidad | D14: Sin Morosidad
B15: De 10 a 29 | C15: =COUNTIFS(moras[EDAD_GRUPO], ">=10", moras[EDAD_GRUPO], "<30", moras[INDICADOR_MOROSO], "SI") -> 122 | D15: =COUNTIFS(moras[EDAD_GRUPO], ">=10", moras[EDAD_GRUPO], "<30", moras[INDICADOR_MOROSO], "NO") -> 978
B16: de 30 a 59 | C16: =COUNTIFS(moras[EDAD_GRUPO], ">=30", moras[EDAD_GRUPO], "<60", moras[INDICADOR_MOROSO], "SI") -> 650 | D16: =COUNTIFS(moras[EDAD_GRUPO], ">=30", moras[EDAD_GRUPO], "<60", moras[INDICADOR_MOROSO], "NO") -> 2661
B17: De 60 a 90 | C17: =COUNTIFS(moras[EDAD_GRUPO], ">=60", moras[EDAD_GRUPO], "<=90", moras[INDICADOR_MOROSO], "SI") -> 98 | D17: =COUNTIFS(moras[EDAD_GRUPO], ">=60", moras[EDAD_GRUPO], "<=90", moras[INDICADOR_MOROSO], "NO") -> 491
